<?xml version='1.0'?>
<sdf version='1.6'>
  <model name='gazebo_finally1'>
    <link name='link_0'>
      <inertial>
        <mass>0.268461</mass>
        <inertia>
          <ixx>0.019799</ixx>
          <ixy>0</ixy>
          <ixz>0</ixz>
          <iyy>0.0470204</iyy>
          <iyz>0</iyz>
          <izz>0.064964</izz>
        </inertia>
        <pose frame=''>0 0 0 0 -0 0</pose>
      </inertial>
      <pose frame=''>0.399341 -0.379491 0.647925 0.1 -0 0</pose>
      <gravity>1</gravity>
      <self_collide>0</self_collide>
      <kinematic>0</kinematic>
      <enable_wind>0</enable_wind>
      <visual name='visual'>
        <pose frame=''>0 0 0 0 -0 0</pose>
        <geometry>
          <box>
            <size>1.43538 0.918441 0.203637</size>
          </box>
        </geometry>
        <material>
          <lighting>1</lighting>
          <script>
            <uri>file://media/materials/scripts/gazebo.material</uri>
            <name>Gazebo/Grey</name>
          </script>
          <shader type='vertex'>
            <normal_map>__default__</normal_map>
          </shader>
          <ambient>0.3 0.3 0.3 1</ambient>
          <diffuse>0.7 0.7 0.7 1</diffuse>
          <specular>0.01 0.01 0.01 1</specular>
          <emissive>0 0 0 1</emissive>
        </material>
        <transparency>0</transparency>
        <cast_shadows>1</cast_shadows>
      </visual>
      <collision name='collision'>
        <laser_retro>0</laser_retro>
        <max_contacts>10</max_contacts>
        <pose frame=''>0 0 0 0 -0 0</pose>
        <geometry>
          <box>
            <size>1.43538 0.918441 0.203637</size>
          </box>
        </geometry>
        <surface>
          <friction>
            <ode>
              <mu>1</mu>
              <mu2>1</mu2>
              <fdir1>0 0 0</fdir1>
              <slip1>0</slip1>
              <slip2>0</slip2>
            </ode>
            <torsional>
              <coefficient>1</coefficient>
              <patch_radius>0</patch_radius>
              <surface_radius>0</surface_radius>
              <use_patch_radius>1</use_patch_radius>
              <ode>
                <slip>0</slip>
              </ode>
            </torsional>
          </friction>
          <bounce>
            <restitution_coefficient>0</restitution_coefficient>
            <threshold>1e+06</threshold>
          </bounce>
          <contact>
            <collide_without_contact>0</collide_without_contact>
            <collide_without_contact_bitmask>1</collide_without_contact_bitmask>
            <collide_bitmask>1</collide_bitmask>
            <ode>
              <soft_cfm>0</soft_cfm>
              <soft_erp>0.2</soft_erp>
              <kp>1e+13</kp>
              <kd>1</kd>
              <max_vel>0.01</max_vel>
              <min_depth>0</min_depth>
            </ode>
            <bullet>
              <split_impulse>1</split_impulse>
              <split_impulse_penetration_threshold>-0.01</split_impulse_penetration_threshold>
              <soft_cfm>0</soft_cfm>
              <soft_erp>0.2</soft_erp>
              <kp>1e+13</kp>
              <kd>1</kd>
            </bullet>
          </contact>
        </surface>
      </collision>
    </link>
    <link name='link_2_clone'>
      <inertial>
        <mass>1</mass>
        <inertia>
          <ixx>0.145833</ixx>
          <ixy>0</ixy>
          <ixz>0</ixz>
          <iyy>0.145833</iyy>
          <iyz>0</iyz>
          <izz>0.125</izz>
        </inertia>
        <pose frame=''>0 0 0 1.5707 -0 0</pose>
      </inertial>
      <pose frame=''>0.831087 0.215329 0.738794 1.6717 -0 0</pose>
      <gravity>1</gravity>
      <self_collide>0</self_collide>
      <kinematic>0</kinematic>
      <enable_wind>0</enable_wind>
      <visual name='visual'>
        <pose frame=''>0 0 0 0 -0 0</pose>
        <geometry>
          <cylinder>
            <radius>0.3</radius>
            <length>0.25</length>
          </cylinder>
        </geometry>
        <material>
          <lighting>1</lighting>
          <script>
            <uri>file://media/materials/scripts/gazebo.material</uri>
            <name>Gazebo/Grey</name>
          </script>
          <shader type='vertex'>
            <normal_map>__default__</normal_map>
          </shader>
          <ambient>0.3 0.3 0.3 1</ambient>
          <diffuse>0.7 0.7 0.7 1</diffuse>
          <specular>0.01 0.01 0.01 1</specular>
          <emissive>0 0 0 1</emissive>
        </material>
        <transparency>0</transparency>
        <cast_shadows>1</cast_shadows>
      </visual>
      <collision name='collision'>
        <laser_retro>0</laser_retro>
        <max_contacts>10</max_contacts>
        <pose frame=''>0 0 0 0 -0 0</pose>
        <geometry>
          <cylinder>
            <radius>0.3</radius>
            <length>0.25</length>
          </cylinder>
        </geometry>
        <surface>
          <friction>
            <ode>
              <mu>1</mu>
              <mu2>1</mu2>
              <fdir1>0 0 0</fdir1>
              <slip1>0</slip1>
              <slip2>0</slip2>
            </ode>
            <torsional>
              <coefficient>1</coefficient>
              <patch_radius>0</patch_radius>
              <surface_radius>0</surface_radius>
              <use_patch_radius>1</use_patch_radius>
              <ode>
                <slip>0</slip>
              </ode>
            </torsional>
          </friction>
          <bounce>
            <restitution_coefficient>0</restitution_coefficient>
            <threshold>1e+06</threshold>
          </bounce>
          <contact>
            <collide_without_contact>0</collide_without_contact>
            <collide_without_contact_bitmask>1</collide_without_contact_bitmask>
            <collide_bitmask>1</collide_bitmask>
            <ode>
              <soft_cfm>0</soft_cfm>
              <soft_erp>0.2</soft_erp>
              <kp>1e+13</kp>
              <kd>1</kd>
              <max_vel>0.01</max_vel>
              <min_depth>0</min_depth>
            </ode>
            <bullet>
              <split_impulse>1</split_impulse>
              <split_impulse_penetration_threshold>-0.01</split_impulse_penetration_threshold>
              <soft_cfm>0</soft_cfm>
              <soft_erp>0.2</soft_erp>
              <kp>1e+13</kp>
              <kd>1</kd>
            </bullet>
          </contact>
        </surface>
      </collision>
    </link>
    <link name='link_2_clone_clone'>
      <inertial>
        <mass>1</mass>
        <inertia>
          <ixx>0.145833</ixx>
          <ixy>0</ixy>
          <ixz>0</ixz>
          <iyy>0.145833</iyy>
          <iyz>0</iyz>
          <izz>0.125</izz>
        </inertia>
        <pose frame=''>0 0 0 0 -0 0</pose>
      </inertial>
      <pose frame=''>0.814783 -0.985352 0.594172 1.675 0.001809 -0.014974</pose>
      <gravity>1</gravity>
      <self_collide>0</self_collide>
      <kinematic>0</kinematic>
      <enable_wind>0</enable_wind>
      <visual name='visual'>
        <pose frame=''>0 0 0 0 -0 0</pose>
        <geometry>
          <cylinder>
            <radius>0.3</radius>
            <length>0.25</length>
          </cylinder>
        </geometry>
        <material>
          <lighting>1</lighting>
          <script>
            <uri>file://media/materials/scripts/gazebo.material</uri>
            <name>Gazebo/Grey</name>
          </script>
          <shader type='vertex'>
            <normal_map>__default__</normal_map>
          </shader>
          <ambient>0.3 0.3 0.3 1</ambient>
          <diffuse>0.7 0.7 0.7 1</diffuse>
          <specular>0.01 0.01 0.01 1</specular>
          <emissive>0 0 0 1</emissive>
        </material>
        <transparency>0</transparency>
        <cast_shadows>1</cast_shadows>
      </visual>
      <collision name='collision'>
        <laser_retro>0</laser_retro>
        <max_contacts>10</max_contacts>
        <pose frame=''>0 0 0 0 -0 0</pose>
        <geometry>
          <cylinder>
            <radius>0.3</radius>
            <length>0.25</length>
          </cylinder>
        </geometry>
        <surface>
          <friction>
            <ode>
              <mu>1</mu>
              <mu2>1</mu2>
              <fdir1>0 0 0</fdir1>
              <slip1>0</slip1>
              <slip2>0</slip2>
            </ode>
            <torsional>
              <coefficient>1</coefficient>
              <patch_radius>0</patch_radius>
              <surface_radius>0</surface_radius>
              <use_patch_radius>1</use_patch_radius>
              <ode>
                <slip>0</slip>
              </ode>
            </torsional>
          </friction>
          <bounce>
            <restitution_coefficient>0</restitution_coefficient>
            <threshold>1e+06</threshold>
          </bounce>
          <contact>
            <collide_without_contact>0</collide_without_contact>
            <collide_without_contact_bitmask>1</collide_without_contact_bitmask>
            <collide_bitmask>1</collide_bitmask>
            <ode>
              <soft_cfm>0</soft_cfm>
              <soft_erp>0.2</soft_erp>
              <kp>1e+13</kp>
              <kd>1</kd>
              <max_vel>0.01</max_vel>
              <min_depth>0</min_depth>
            </ode>
            <bullet>
              <split_impulse>1</split_impulse>
              <split_impulse_penetration_threshold>-0.01</split_impulse_penetration_threshold>
              <soft_cfm>0</soft_cfm>
              <soft_erp>0.2</soft_erp>
              <kp>1e+13</kp>
              <kd>1</kd>
            </bullet>
          </contact>
        </surface>
      </collision>
    </link>
    <link name='link_5'>
      <inertial>
        <mass>1</mass>
        <inertia>
          <ixx>0.1</ixx>
          <ixy>0</ixy>
          <ixz>0</ixz>
          <iyy>0.1</iyy>
          <iyz>0</iyz>
          <izz>0.1</izz>
        </inertia>
        <pose frame=''>0 0 0 0 -0 0</pose>
      </inertial>
      <pose frame=''>-0.203161 -0.358328 0.551395 -0 -0 -0</pose>
      <gravity>1</gravity>
      <self_collide>0</self_collide>
      <kinematic>0</kinematic>
      <enable_wind>0</enable_wind>
      <visual name='visual'>
        <pose frame=''>0 0 0 0 -0 0</pose>
        <geometry>
          <sphere>
            <radius>0.12</radius>
          </sphere>
        </geometry>
        <material>
          <lighting>1</lighting>
          <script>
            <uri>file://media/materials/scripts/gazebo.material</uri>
            <name>Gazebo/Grey</name>
          </script>
          <shader type='vertex'>
            <normal_map>__default__</normal_map>
          </shader>
          <ambient>0.3 0.3 0.3 1</ambient>
          <diffuse>0.7 0.7 0.7 1</diffuse>
          <specular>0.01 0.01 0.01 1</specular>
          <emissive>0 0 0 1</emissive>
        </material>
        <transparency>0</transparency>
        <cast_shadows>1</cast_shadows>
      </visual>
      <collision name='collision'>
        <laser_retro>0</laser_retro>
        <max_contacts>10</max_contacts>
        <pose frame=''>0 0 0 0 -0 0</pose>
        <geometry>
          <sphere>
            <radius>0.12</radius>
          </sphere>
        </geometry>
        <surface>
          <friction>
            <ode>
              <mu>1</mu>
              <mu2>1</mu2>
              <fdir1>0 0 0</fdir1>
              <slip1>0</slip1>
              <slip2>0</slip2>
            </ode>
            <torsional>
              <coefficient>1</coefficient>
              <patch_radius>0</patch_radius>
              <surface_radius>0</surface_radius>
              <use_patch_radius>1</use_patch_radius>
              <ode>
                <slip>0</slip>
              </ode>
            </torsional>
          </friction>
          <bounce>
            <restitution_coefficient>0</restitution_coefficient>
            <threshold>1e+06</threshold>
          </bounce>
          <contact>
            <collide_without_contact>0</collide_without_contact>
            <collide_without_contact_bitmask>1</collide_without_contact_bitmask>
            <collide_bitmask>1</collide_bitmask>
            <ode>
              <soft_cfm>0</soft_cfm>
              <soft_erp>0.2</soft_erp>
              <kp>1e+13</kp>
              <kd>1</kd>
              <max_vel>0.01</max_vel>
              <min_depth>0</min_depth>
            </ode>
            <bullet>
              <split_impulse>1</split_impulse>
              <split_impulse_penetration_threshold>-0.01</split_impulse_penetration_threshold>
              <soft_cfm>0</soft_cfm>
              <soft_erp>0.2</soft_erp>
              <kp>1e+13</kp>
              <kd>1</kd>
            </bullet>
          </contact>
        </surface>
      </collision>
    </link>
    <model name='camera'>
      <pose frame=''>0.906951 -0.372268 0.81011 0.116955 -0 0</pose>
      <link name='link'>
        <inertial>
          <mass>0.1</mass>
          <inertia>
            <ixx>0.000166667</ixx>
            <iyy>0.000166667</iyy>
            <izz>0.000166667</izz>
            <ixy>0</ixy>
            <ixz>0</ixz>
            <iyz>0</iyz>
          </inertia>
        </inertial>
        <collision name='collision'>
          <geometry>
            <box>
              <size>0.1 0.1 0.1</size>
            </box>
          </geometry>
          <max_contacts>10</max_contacts>
          <surface>
            <contact>
              <ode/>
            </contact>
            <bounce/>
            <friction>
              <torsional>
                <ode/>
              </torsional>
              <ode/>
            </friction>
          </surface>
        </collision>
        <visual name='visual'>
          <geometry>
            <box>
              <size>0.1 0.1 0.1</size>
            </box>
          </geometry>
        </visual>
        <sensor name='camera' type='camera'>
          <camera name='__default__'>
            <horizontal_fov>1.047</horizontal_fov>
            <image>
              <width>320</width>
              <height>240</height>
            </image>
            <clip>
              <near>0.1</near>
              <far>100</far>
            </clip>
          </camera>
          <always_on>1</always_on>
          <update_rate>30</update_rate>
          <visualize>1</visualize>
        </sensor>
        <self_collide>0</self_collide>
        <enable_wind>0</enable_wind>
        <kinematic>0</kinematic>
      </link>
    </model>
    <model name='intel_realsense_r200'>
      <pose frame=''>0.527541 -1.17727 0.01 -0 -0 -0</pose>
      <link name='link'>
        <inertial>
          <mass>0.2</mass>
          <inertia>
            <ixx>0.00014395</ixx>
            <ixy>0</ixy>
            <ixz>0</ixz>
            <iyy>3.84e-06</iyy>
            <iyz>0</iyz>
            <izz>0.00014136</izz>
          </inertia>
        </inertial>
        <collision name='collision'>
          <geometry>
            <box>
              <size>0.008 0.13 0.02</size>
            </box>
          </geometry>
          <surface>
            <contact>
              <ode>
                <max_vel>0.1</max_vel>
                <min_depth>0.001</min_depth>
              </ode>
            </contact>
            <friction>
              <ode>
                <mu>0.4</mu>
                <mu2>0.4</mu2>
              </ode>
              <torsional>
                <ode/>
              </torsional>
            </friction>
            <bounce/>
          </surface>
          <max_contacts>10</max_contacts>
        </collision>
        <visual name='visual'>
          <geometry>
            <mesh>
              <uri>model://intel_realsense_r200/meshes/realsense_r200.dae</uri>
            </mesh>
          </geometry>
        </visual>
        <sensor name='camera' type='depth'>
          <pose frame=''>0.001 -0.045 0.003 0 -0 0</pose>
          <update_rate>60</update_rate>
          <camera name='__default__'>
            <horizontal_fov>0.976899</horizontal_fov>
            <image>
              <width>480</width>
              <height>360</height>
              <format>R8G8B8</format>
            </image>
            <clip>
              <near>0.5</near>
              <far>10</far>
            </clip>
          </camera>
        </sensor>
        <self_collide>0</self_collide>
        <enable_wind>0</enable_wind>
        <kinematic>0</kinematic>
      </link>
    </model>
    <joint name='link_0_JOINT_1' type='revolute'>
      <parent>link_0</parent>
      <child>link_2_clone</child>
      <pose frame=''>0 0 0 0 -0 0</pose>
      <axis>
        <xyz>0 0 1</xyz>
        <use_parent_model_frame>0</use_parent_model_frame>
        <limit>
          <lower>-1.79769e+308</lower>
          <upper>1.79769e+308</upper>
          <effort>-1</effort>
          <velocity>-1</velocity>
        </limit>
        <dynamics>
          <spring_reference>0</spring_reference>
          <spring_stiffness>0</spring_stiffness>
          <damping>0</damping>
        </dynamics>
      </axis>
      <physics>
        <ode>
          <limit>
            <cfm>0</cfm>
            <erp>0.2</erp>
          </limit>
          <suspension>
            <cfm>0</cfm>
            <erp>0.2</erp>
          </suspension>
        </ode>
      </physics>
    </joint>
    <joint name='link_0_JOINT_2' type='revolute'>
      <parent>link_0</parent>
      <child>link_2_clone_clone</child>
      <pose frame=''>0 0 0 0 -0 0</pose>
      <axis>
        <xyz>-0 -0 -1</xyz>
        <use_parent_model_frame>0</use_parent_model_frame>
        <limit>
          <lower>-1.79769e+308</lower>
          <upper>1.79769e+308</upper>
          <effort>-1</effort>
          <velocity>-1</velocity>
        </limit>
        <dynamics>
          <spring_reference>0</spring_reference>
          <spring_stiffness>0</spring_stiffness>
          <damping>0</damping>
        </dynamics>
      </axis>
      <physics>
        <ode>
          <limit>
            <cfm>0</cfm>
            <erp>0.2</erp>
          </limit>
          <suspension>
            <cfm>0</cfm>
            <erp>0.2</erp>
          </suspension>
        </ode>
      </physics>
    </joint>
    <joint name='link_0_JOINT_3' type='ball'>
      <parent>link_0</parent>
      <child>link_5</child>
      <pose frame=''>0 0 0 0 -0 0</pose>
      <physics>
        <ode>
          <limit>
            <cfm>0</cfm>
            <erp>0.2</erp>
          </limit>
          <suspension>
            <cfm>0</cfm>
            <erp>0.2</erp>
          </suspension>
        </ode>
      </physics>
    </joint>
    <joint name='link_0_JOINT_4' type='fixed'>
      <parent>link_0</parent>
      <child>camera::link</child>
      <pose frame=''>0 0 0 0 -0 0</pose>
      <physics>
        <ode>
          <limit>
            <cfm>0</cfm>
            <erp>0.2</erp>
          </limit>
          <suspension>
            <cfm>0</cfm>
            <erp>0.2</erp>
          </suspension>
        </ode>
      </physics>
    </joint>
    <static>0</static>
    <allow_auto_disable>1</allow_auto_disable>
    <plugin name='followerfinally' filename='libfollowerfinallyplugin.so'/>
  </model>
</sdf>
